Workbook

Sheet Start Here
A1: Olist Marketing Funnel – Real Data Report
A2: Source: Marketing Funnel by Olist (Kaggle, CC BY-NC-SA 4.0) · analysis by Karan Lodha
A4: Sheet | B4: What it answers
A5: Settings | B5: Analysis window start. Change the yellow cell only.
A6: Monthly | B6: Lead volume and conversion by month – and why 2017 is excluded
A7: Channels | B7: Which marketing channels bring leads that become sellers?
A8: Landing Pages | B8: Do some sign-up pages produce much better leads?
A9: Page x Channel | B9: Is the page effect real, or just better traffic?
A10: Time to Close | B10: How long from first contact to a won deal?
A11: Closers | B11: How dependent are we on a few sales reps?
A12: Data Quality | B12: What we can and can't trust in this data
A13: MQLs / Deals | B13: Raw Kaggle tables. Teal columns on MQLs join each lead to its deal with MATCH/INDEX.
A16: Funnel: a marketing qualified lead (MQL) is a seller who filled in a sign-up form; a deal is a seller the sales team signed onto the Olist marketplace.

Sheet Settings
A1: Settings
A2: Change the yellow cell; every report sheet recalculates.
A4: Setting | C4: Value | D4: Why
A5: Analysis window: leads from | C5: 43101 | D5: Deal data starts Dec 2017, so earlier leads look like they never convert.
A8: Leads in window | C8: =SUM(MQLs!$K$2:$K$8001)
A9: Deals in window | C9: =COUNTIFS(MQLs!$K$2:$K$8001,1,MQLs!$G$2:$G$8001,1)
A10: Conversion in window | C10: =C9/C8
A11: Earliest deal in file | C11: =MIN(Deals!$E$2:$E$843)

Sheet Monthly
A1: Leads and Conversion by Month
A2: Conversion = leads that became a deal / leads
A4: Lead month | B4: Leads | C4: Deals | D4: Conversion | E4: In window?
A5: 2017-06 | B5: =COUNTIFS(MQLs!$C$2:$C$8001,$A5) | C5: =COUNTIFS(MQLs!$C$2:$C$8001,$A5,MQLs!$G$2:$G$8001,1) | D5: =IFERROR(C5/B5,0) | E5: =IF(DATEVALUE($A5&"-01")>=Settings!$C$5,"yes","no – deal data incomplete")
A6: 2017-07 | B6: =COUNTIFS(MQLs!$C$2:$C$8001,$A6) | C6: =COUNTIFS(MQLs!$C$2:$C$8001,$A6,MQLs!$G$2:$G$8001,1) | D6: =IFERROR(C6/B6,0) | E6: =IF(DATEVALUE($A6&"-01")>=Settings!$C$5,"yes","no – deal data incomplete")
A7: 2017-08 | B7: =COUNTIFS(MQLs!$C$2:$C$8001,$A7) | C7: =COUNTIFS(MQLs!$C$2:$C$8001,$A7,MQLs!$G$2:$G$8001,1) | D7: =IFERROR(C7/B7,0) | E7: =IF(DATEVALUE($A7&"-01")>=Settings!$C$5,"yes","no – deal data incomplete")
A8: 2017-09 | B8: =COUNTIFS(MQLs!$C$2:$C$8001,$A8) | C8: =COUNTIFS(MQLs!$C$2:$C$8001,$A8,MQLs!$G$2:$G$8001,1) | D8: =IFERROR(C8/B8,0) | E8: =IF(DATEVALUE($A8&"-01")>=Settings!$C$5,"yes","no – deal data incomplete")
A9: 2017-10 | B9: =COUNTIFS(MQLs!$C$2:$C$8001,$A9) | C9: =COUNTIFS(MQLs!$C$2:$C$8001,$A9,MQLs!$G$2:$G$8001,1) | D9: =IFERROR(C9/B9,0) | E9: =IF(DATEVALUE($A9&"-01")>=Settings!$C$5,"yes","no – deal data incomplete")
A10: 2017-11 | B10: =COUNTIFS(MQLs!$C$2:$C$8001,$A10) | C10: =COUNTIFS(MQLs!$C$2:$C$8001,$A10,MQLs!$G$2:$G$8001,1) | D10: =IFERROR(C10/B10,0) | E10: =IF(DATEVALUE($A10&"-01")>=Settings!$C$5,"yes","no – deal data incomplete")
A11: 2017-12 | B11: =COUNTIFS(MQLs!$C$2:$C$8001,$A11) | C11: =COUNTIFS(MQLs!$C$2:$C$8001,$A11,MQLs!$G$2:$G$8001,1) | D11: =IFERROR(C11/B11,0) | E11: =IF(DATEVALUE($A11&"-01")>=Settings!$C$5,"yes","no – deal data incomplete")
A12: 2018-01 | B12: =COUNTIFS(MQLs!$C$2:$C$8001,$A12) | C12: =COUNTIFS(MQLs!$C$2:$C$8001,$A12,MQLs!$G$2:$G$8001,1) | D12: =IFERROR(C12/B12,0) | E12: =IF(DATEVALUE($A12&"-01")>=Settings!$C$5,"yes","no – deal data incomplete")
A13: 2018-02 | B13: =COUNTIFS(MQLs!$C$2:$C$8001,$A13) | C13: =COUNTIFS(MQLs!$C$2:$C$8001,$A13,MQLs!$G$2:$G$8001,1) | D13: =IFERROR(C13/B13,0) | E13: =IF(DATEVALUE($A13&"-01")>=Settings!$C$5,"yes","no – deal data incomplete")
A14: 2018-03 | B14: =COUNTIFS(MQLs!$C$2:$C$8001,$A14) | C14: =COUNTIFS(MQLs!$C$2:$C$8001,$A14,MQLs!$G$2:$G$8001,1) | D14: =IFERROR(C14/B14,0) | E14: =IF(DATEVALUE($A14&"-01")>=Settings!$C$5,"yes","no – deal data incomplete")
A15: 2018-04 | B15: =COUNTIFS(MQLs!$C$2:$C$8001,$A15) | C15: =COUNTIFS(MQLs!$C$2:$C$8001,$A15,MQLs!$G$2:$G$8001,1) | D15: =IFERROR(C15/B15,0) | E15: =IF(DATEVALUE($A15&"-01")>=Settings!$C$5,"yes","no – deal data incomplete")
A16: 2018-05 | B16: =COUNTIFS(MQLs!$C$2:$C$8001,$A16) | C16: =COUNTIFS(MQLs!$C$2:$C$8001,$A16,MQLs!$G$2:$G$8001,1) | D16: =IFERROR(C16/B16,0) | E16: =IF(DATEVALUE($A16&"-01")>=Settings!$C$5,"yes","no – deal data incomplete")
A18: 2017 conversion is near zero because the deals file starts in Dec 2017 – a data-extract artefact, not a sales improvement in 2018.

Sheet Channels
A1: Channel Performance (analysis window)
A2: Origin = how the lead found the sign-up page
A4: Channel (origin) | B4: Leads | C4: Share of leads | D4: Deals | E4: Conversion | F4: vs average | G4: Avg days to close
A5: organic_search | B5: =COUNTIFS(MQLs!$E$2:$E$8001,$A5,MQLs!$K$2:$K$8001,1) | C5: =IFERROR(B5/$B$16,0) | D5: =COUNTIFS(MQLs!$E$2:$E$8001,$A5,MQLs!$K$2:$K$8001,1,MQLs!$G$2:$G$8001,1) | E5: =IFERROR(D5/B5,0) | F5: =(E5-$E$16)*100 | G5: =IFERROR(AVERAGEIFS(MQLs!$J$2:$J$8001,MQLs!$E$2:$E$8001,$A5,MQLs!$K$2:$K$8001,1,MQLs!$J$2:$J$8001,">=0"),0)
A6: paid_search | B6: =COUNTIFS(MQLs!$E$2:$E$8001,$A6,MQLs!$K$2:$K$8001,1) | C6: =IFERROR(B6/$B$16,0) | D6: =COUNTIFS(MQLs!$E$2:$E$8001,$A6,MQLs!$K$2:$K$8001,1,MQLs!$G$2:$G$8001,1) | E6: =IFERROR(D6/B6,0) | F6: =(E6-$E$16)*100 | G6: =IFERROR(AVERAGEIFS(MQLs!$J$2:$J$8001,MQLs!$E$2:$E$8001,$A6,MQLs!$K$2:$K$8001,1,MQLs!$J$2:$J$8001,">=0"),0)
A7: social | B7: =COUNTIFS(MQLs!$E$2:$E$8001,$A7,MQLs!$K$2:$K$8001,1) | C7: =IFERROR(B7/$B$16,0) | D7: =COUNTIFS(MQLs!$E$2:$E$8001,$A7,MQLs!$K$2:$K$8001,1,MQLs!$G$2:$G$8001,1) | E7: =IFERROR(D7/B7,0) | F7: =(E7-$E$16)*100 | G7: =IFERROR(AVERAGEIFS(MQLs!$J$2:$J$8001,MQLs!$E$2:$E$8001,$A7,MQLs!$K$2:$K$8001,1,MQLs!$J$2:$J$8001,">=0"),0)
A8: unknown | B8: =COUNTIFS(MQLs!$E$2:$E$8001,$A8,MQLs!$K$2:$K$8001,1) | C8: =IFERROR(B8/$B$16,0) | D8: =COUNTIFS(MQLs!$E$2:$E$8001,$A8,MQLs!$K$2:$K$8001,1,MQLs!$G$2:$G$8001,1) | E8: =IFERROR(D8/B8,0) | F8: =(E8-$E$16)*100 | G8: =IFERROR(AVERAGEIFS(MQLs!$J$2:$J$8001,MQLs!$E$2:$E$8001,$A8,MQLs!$K$2:$K$8001,1,MQLs!$J$2:$J$8001,">=0"),0)
A9: direct_traffic | B9: =COUNTIFS(MQLs!$E$2:$E$8001,$A9,MQLs!$K$2:$K$8001,1) | C9: =IFERROR(B9/$B$16,0) | D9: =COUNTIFS(MQLs!$E$2:$E$8001,$A9,MQLs!$K$2:$K$8001,1,MQLs!$G$2:$G$8001,1) | E9: =IFERROR(D9/B9,0) | F9: =(E9-$E$16)*100 | G9: =IFERROR(AVERAGEIFS(MQLs!$J$2:$J$8001,MQLs!$E$2:$E$8001,$A9,MQLs!$K$2:$K$8001,1,MQLs!$J$2:$J$8001,">=0"),0)
A10: email | B10: =COUNTIFS(MQLs!$E$2:$E$8001,$A10,MQLs!$K$2:$K$8001,1) | C10: =IFERROR(B10/$B$16,0) | D10: =COUNTIFS(MQLs!$E$2:$E$8001,$A10,MQLs!$K$2:$K$8001,1,MQLs!$G$2:$G$8001,1) | E10: =IFERROR(D10/B10,0) | F10: =(E10-$E$16)*100 | G10: =IFERROR(AVERAGEIFS(MQLs!$J$2:$J$8001,MQLs!$E$2:$E$8001,$A10,MQLs!$K$2:$K$8001,1,MQLs!$J$2:$J$8001,">=0"),0)
A11: referral | B11: =COUNTIFS(MQLs!$E$2:$E$8001,$A11,MQLs!$K$2:$K$8001,1) | C11: =IFERROR(B11/$B$16,0) | D11: =COUNTIFS(MQLs!$E$2:$E$8001,$A11,MQLs!$K$2:$K$8001,1,MQLs!$G$2:$G$8001,1) | E11: =IFERROR(D11/B11,0) | F11: =(E11-$E$16)*100 | G11: =IFERROR(AVERAGEIFS(MQLs!$J$2:$J$8001,MQLs!$E$2:$E$8001,$A11,MQLs!$K$2:$K$8001,1,MQLs!$J$2:$J$8001,">=0"),0)
A12: other | B12: =COUNTIFS(MQLs!$E$2:$E$8001,$A12,MQLs!$K$2:$K$8001,1) | C12: =IFERROR(B12/$B$16,0) | D12: =COUNTIFS(MQLs!$E$2:$E$8001,$A12,MQLs!$K$2:$K$8001,1,MQLs!$G$2:$G$8001,1) | E12: =IFERROR(D12/B12,0) | F12: =(E12-$E$16)*100 | G12: =IFERROR(AVERAGEIFS(MQLs!$J$2:$J$8001,MQLs!$E$2:$E$8001,$A12,MQLs!$K$2:$K$8001,1,MQLs!$J$2:$J$8001,">=0"),0)
A13: display | B13: =COUNTIFS(MQLs!$E$2:$E$8001,$A13,MQLs!$K$2:$K$8001,1) | C13: =IFERROR(B13/$B$16,0) | D13: =COUNTIFS(MQLs!$E$2:$E$8001,$A13,MQLs!$K$2:$K$8001,1,MQLs!$G$2:$G$8001,1) | E13: =IFERROR(D13/B13,0) | F13: =(E13-$E$16)*100 | G13: =IFERROR(AVERAGEIFS(MQLs!$J$2:$J$8001,MQLs!$E$2:$E$8001,$A13,MQLs!$K$2:$K$8001,1,MQLs!$J$2:$J$8001,">=0"),0)
A14: (missing) | B14: =COUNTIFS(MQLs!$E$2:$E$8001,$A14,MQLs!$K$2:$K$8001,1) | C14: =IFERROR(B14/$B$16,0) | D14: =COUNTIFS(MQLs!$E$2:$E$8001,$A14,MQLs!$K$2:$K$8001,1,MQLs!$G$2:$G$8001,1) | E14: =IFERROR(D14/B14,0) | F14: =(E14-$E$16)*100 | G14: =IFERROR(AVERAGEIFS(MQLs!$J$2:$J$8001,MQLs!$E$2:$E$8001,$A14,MQLs!$K$2:$K$8001,1,MQLs!$J$2:$J$8001,">=0"),0)
A15: other_publicities | B15: =COUNTIFS(MQLs!$E$2:$E$8001,$A15,MQLs!$K$2:$K$8001,1) | C15: =IFERROR(B15/$B$16,0) | D15: =COUNTIFS(MQLs!$E$2:$E$8001,$A15,MQLs!$K$2:$K$8001,1,MQLs!$G$2:$G$8001,1) | E15: =IFERROR(D15/B15,0) | F15: =(E15-$E$16)*100 | G15: =IFERROR(AVERAGEIFS(MQLs!$J$2:$J$8001,MQLs!$E$2:$E$8001,$A15,MQLs!$K$2:$K$8001,1,MQLs!$J$2:$J$8001,">=0"),0)
A16: Total | B16: =SUM(B5:B15) | C16: =SUM(C5:C15) | D16: =SUM(D5:D15) | E16: =IFERROR(D16/B16,0)
A18: Read: social is 18% of leads but converts at less than half the average; 'unknown' converts best – a tracking gap that hides the best leads.

Sheet Landing Pages
A1: Landing Page Performance (analysis window)
A2: The 10 pages with the most leads; the long tail is grouped below
A4: Page | B4: Landing page id | C4: Leads | D4: Deals | E4: Conversion | F4: Share of leads
A5: Page 1 | B5: b76ef37428e6799c421989521c0e5077 | C5: =COUNTIFS(MQLs!$D$2:$D$8001,$B5,MQLs!$K$2:$K$8001,1) | D5: =COUNTIFS(MQLs!$D$2:$D$8001,$B5,MQLs!$K$2:$K$8001,1,MQLs!$G$2:$G$8001,1) | E5: =IFERROR(D5/C5,0) | F5: =IFERROR(C5/$C$16,0)
A6: Page 2 | B6: 22c29808c4f815213303f8933030604c | C6: =COUNTIFS(MQLs!$D$2:$D$8001,$B6,MQLs!$K$2:$K$8001,1) | D6: =COUNTIFS(MQLs!$D$2:$D$8001,$B6,MQLs!$K$2:$K$8001,1,MQLs!$G$2:$G$8001,1) | E6: =IFERROR(D6/C6,0) | F6: =IFERROR(C6/$C$16,0)
A7: Page 3 | B7: 58326e62183c14b0c03085c33b9fdc44 | C7: =COUNTIFS(MQLs!$D$2:$D$8001,$B7,MQLs!$K$2:$K$8001,1) | D7: =COUNTIFS(MQLs!$D$2:$D$8001,$B7,MQLs!$K$2:$K$8001,1,MQLs!$G$2:$G$8001,1) | E7: =IFERROR(D7/C7,0) | F7: =IFERROR(C7/$C$16,0)
A8: Page 4 | B8: ce1a65abd0973638f1c887a6efcfa82d | C8: =COUNTIFS(MQLs!$D$2:$D$8001,$B8,MQLs!$K$2:$K$8001,1) | D8: =COUNTIFS(MQLs!$D$2:$D$8001,$B8,MQLs!$K$2:$K$8001,1,MQLs!$G$2:$G$8001,1) | E8: =IFERROR(D8/C8,0) | F8: =IFERROR(C8/$C$16,0)
A9: Page 5 | B9: 88740e65d5d6b056e0cda098e1ea6313 | C9: =COUNTIFS(MQLs!$D$2:$D$8001,$B9,MQLs!$K$2:$K$8001,1) | D9: =COUNTIFS(MQLs!$D$2:$D$8001,$B9,MQLs!$K$2:$K$8001,1,MQLs!$G$2:$G$8001,1) | E9: =IFERROR(D9/C9,0) | F9: =IFERROR(C9/$C$16,0)
A10: Page 6 | B10: 40dec9f3d5259a3d2dbcdab2114fae47 | C10: =COUNTIFS(MQLs!$D$2:$D$8001,$B10,MQLs!$K$2:$K$8001,1) | D10: =COUNTIFS(MQLs!$D$2:$D$8001,$B10,MQLs!$K$2:$K$8001,1,MQLs!$G$2:$G$8001,1) | E10: =IFERROR(D10/C10,0) | F10: =IFERROR(C10/$C$16,0)
A11: Page 7 | B11: f017be4dbf86243af5c1ebed0cff36a2 | C11: =COUNTIFS(MQLs!$D$2:$D$8001,$B11,MQLs!$K$2:$K$8001,1) | D11: =COUNTIFS(MQLs!$D$2:$D$8001,$B11,MQLs!$K$2:$K$8001,1,MQLs!$G$2:$G$8001,1) | E11: =IFERROR(D11/C11,0) | F11: =IFERROR(C11/$C$16,0)
A12: Page 8 | B12: e492ee5eaf1697716985cc6f33f9cd9b | C12: =COUNTIFS(MQLs!$D$2:$D$8001,$B12,MQLs!$K$2:$K$8001,1) | D12: =COUNTIFS(MQLs!$D$2:$D$8001,$B12,MQLs!$K$2:$K$8001,1,MQLs!$G$2:$G$8001,1) | E12: =IFERROR(D12/C12,0) | F12: =IFERROR(C12/$C$16,0)
A13: Page 9 | B13: a7982125ff7aa3b2054c6e44f9d28522 | C13: =COUNTIFS(MQLs!$D$2:$D$8001,$B13,MQLs!$K$2:$K$8001,1) | D13: =COUNTIFS(MQLs!$D$2:$D$8001,$B13,MQLs!$K$2:$K$8001,1,MQLs!$G$2:$G$8001,1) | E13: =IFERROR(D13/C13,0) | F13: =IFERROR(C13/$C$16,0)
A14: Page 10 | B14: 73f31a40697cc90a86c1273563ac230e | C14: =COUNTIFS(MQLs!$D$2:$D$8001,$B14,MQLs!$K$2:$K$8001,1) | D14: =COUNTIFS(MQLs!$D$2:$D$8001,$B14,MQLs!$K$2:$K$8001,1,MQLs!$G$2:$G$8001,1) | E14: =IFERROR(D14/C14,0) | F14: =IFERROR(C14/$C$16,0)
A15: All other pages | C15: =C16-SUM(C5:C14) | D15: =D16-SUM(D5:D14) | E15: =IFERROR(D15/C15,0) | F15: =IFERROR(C15/$C$16,0)
A16: Total | C16: =SUM(MQLs!$K$2:$K$8001) | D16: =COUNTIFS(MQLs!$K$2:$K$8001,1,MQLs!$G$2:$G$8001,1) | E16: =IFERROR(D16/C16,0)
A18: Pages 1 and 2 convert at ~22% vs ~10% for the rest. See 'Page x Channel' for whether that is the page or the traffic.

Sheet Page x Channel
A1: Top-2 Pages vs Other Pages, Within Each Channel
A2: If the top pages also win inside the same channel, the page itself is the driver
A4: Top page 1 | B4: b76ef37428e6799c421989521c0e5077
A5: Top page 2 | B5: 22c29808c4f815213303f8933030604c
A7: Channel | B7: Leads – top pages | C7: Conversion – top pages | D7: Leads – other pages | E7: Conversion – other pages | F7: Difference
A8: unknown | B8: =COUNTIFS(MQLs!$E$2:$E$8001,$A8,MQLs!$K$2:$K$8001,1,MQLs!$D$2:$D$8001,$B$4)+COUNTIFS(MQLs!$E$2:$E$8001,$A8,MQLs!$K$2:$K$8001,1,MQLs!$D$2:$D$8001,$B$5) | C8: =IFERROR((COUNTIFS(MQLs!$E$2:$E$8001,$A8,MQLs!$K$2:$K$8001,1,MQLs!$D$2:$D$8001,$B$4,MQLs!$G$2:$G$8001,1)+COUNTIFS(MQLs!$E$2:$E$8001,$A8,MQLs!$K$2:$K$8001,1,MQLs!$D$2:$D$8001,$B$5,MQLs!$G$2:$G$8001,1))/B8,0) | D8: =COUNTIFS(MQLs!$E$2:$E$8001,$A8,MQLs!$K$2:$K$8001,1)-B8 | E8: =IFERROR((COUNTIFS(MQLs!$E$2:$E$8001,$A8,MQLs!$K$2:$K$8001,1,MQLs!$G$2:$G$8001,1)-(COUNTIFS(MQLs!$E$2:$E$8001,$A8,MQLs!$K$2:$K$8001,1,MQLs!$D$2:$D$8001,$B$4,MQLs!$G$2:$G$8001,1)+COUNTIFS(MQLs!$E$2:$E$8001,$A8,MQLs!$K$2:$K$8001,1,MQLs!$D$2:$D$8001,$B$5,MQLs!$G$2:$G$8001,1)))/D8,0) | F8: =(C8-E8)*100
A9: organic_search | B9: =COUNTIFS(MQLs!$E$2:$E$8001,$A9,MQLs!$K$2:$K$8001,1,MQLs!$D$2:$D$8001,$B$4)+COUNTIFS(MQLs!$E$2:$E$8001,$A9,MQLs!$K$2:$K$8001,1,MQLs!$D$2:$D$8001,$B$5) | C9: =IFERROR((COUNTIFS(MQLs!$E$2:$E$8001,$A9,MQLs!$K$2:$K$8001,1,MQLs!$D$2:$D$8001,$B$4,MQLs!$G$2:$G$8001,1)+COUNTIFS(MQLs!$E$2:$E$8001,$A9,MQLs!$K$2:$K$8001,1,MQLs!$D$2:$D$8001,$B$5,MQLs!$G$2:$G$8001,1))/B9,0) | D9: =COUNTIFS(MQLs!$E$2:$E$8001,$A9,MQLs!$K$2:$K$8001,1)-B9 | E9: =IFERROR((COUNTIFS(MQLs!$E$2:$E$8001,$A9,MQLs!$K$2:$K$8001,1,MQLs!$G$2:$G$8001,1)-(COUNTIFS(MQLs!$E$2:$E$8001,$A9,MQLs!$K$2:$K$8001,1,MQLs!$D$2:$D$8001,$B$4,MQLs!$G$2:$G$8001,1)+COUNTIFS(MQLs!$E$2:$E$8001,$A9,MQLs!$K$2:$K$8001,1,MQLs!$D$2:$D$8001,$B$5,MQLs!$G$2:$G$8001,1)))/D9,0) | F9: =(C9-E9)*100
A10: paid_search | B10: =COUNTIFS(MQLs!$E$2:$E$8001,$A10,MQLs!$K$2:$K$8001,1,MQLs!$D$2:$D$8001,$B$4)+COUNTIFS(MQLs!$E$2:$E$8001,$A10,MQLs!$K$2:$K$8001,1,MQLs!$D$2:$D$8001,$B$5) | C10: =IFERROR((COUNTIFS(MQLs!$E$2:$E$8001,$A10,MQLs!$K$2:$K$8001,1,MQLs!$D$2:$D$8001,$B$4,MQLs!$G$2:$G$8001,1)+COUNTIFS(MQLs!$E$2:$E$8001,$A10,MQLs!$K$2:$K$8001,1,MQLs!$D$2:$D$8001,$B$5,MQLs!$G$2:$G$8001,1))/B10,0) | D10: =COUNTIFS(MQLs!$E$2:$E$8001,$A10,MQLs!$K$2:$K$8001,1)-B10 | E10: =IFERROR((COUNTIFS(MQLs!$E$2:$E$8001,$A10,MQLs!$K$2:$K$8001,1,MQLs!$G$2:$G$8001,1)-(COUNTIFS(MQLs!$E$2:$E$8001,$A10,MQLs!$K$2:$K$8001,1,MQLs!$D$2:$D$8001,$B$4,MQLs!$G$2:$G$8001,1)+COUNTIFS(MQLs!$E$2:$E$8001,$A10,MQLs!$K$2:$K$8001,1,MQLs!$D$2:$D$8001,$B$5,MQLs!$G$2:$G$8001,1)))/D10,0) | F10: =(C10-E10)*100
A11: direct_traffic | B11: =COUNTIFS(MQLs!$E$2:$E$8001,$A11,MQLs!$K$2:$K$8001,1,MQLs!$D$2:$D$8001,$B$4)+COUNTIFS(MQLs!$E$2:$E$8001,$A11,MQLs!$K$2:$K$8001,1,MQLs!$D$2:$D$8001,$B$5) | C11: =IFERROR((COUNTIFS(MQLs!$E$2:$E$8001,$A11,MQLs!$K$2:$K$8001,1,MQLs!$D$2:$D$8001,$B$4,MQLs!$G$2:$G$8001,1)+COUNTIFS(MQLs!$E$2:$E$8001,$A11,MQLs!$K$2:$K$8001,1,MQLs!$D$2:$D$8001,$B$5,MQLs!$G$2:$G$8001,1))/B11,0) | D11: =COUNTIFS(MQLs!$E$2:$E$8001,$A11,MQLs!$K$2:$K$8001,1)-B11 | E11: =IFERROR((COUNTIFS(MQLs!$E$2:$E$8001,$A11,MQLs!$K$2:$K$8001,1,MQLs!$G$2:$G$8001,1)-(COUNTIFS(MQLs!$E$2:$E$8001,$A11,MQLs!$K$2:$K$8001,1,MQLs!$D$2:$D$8001,$B$4,MQLs!$G$2:$G$8001,1)+COUNTIFS(MQLs!$E$2:$E$8001,$A11,MQLs!$K$2:$K$8001,1,MQLs!$D$2:$D$8001,$B$5,MQLs!$G$2:$G$8001,1)))/D11,0) | F11: =(C11-E11)*100
A12: referral | B12: =COUNTIFS(MQLs!$E$2:$E$8001,$A12,MQLs!$K$2:$K$8001,1,MQLs!$D$2:$D$8001,$B$4)+COUNTIFS(MQLs!$E$2:$E$8001,$A12,MQLs!$K$2:$K$8001,1,MQLs!$D$2:$D$8001,$B$5) | C12: =IFERROR((COUNTIFS(MQLs!$E$2:$E$8001,$A12,MQLs!$K$2:$K$8001,1,MQLs!$D$2:$D$8001,$B$4,MQLs!$G$2:$G$8001,1)+COUNTIFS(MQLs!$E$2:$E$8001,$A12,MQLs!$K$2:$K$8001,1,MQLs!$D$2:$D$8001,$B$5,MQLs!$G$2:$G$8001,1))/B12,0) | D12: =COUNTIFS(MQLs!$E$2:$E$8001,$A12,MQLs!$K$2:$K$8001,1)-B12 | E12: =IFERROR((COUNTIFS(MQLs!$E$2:$E$8001,$A12,MQLs!$K$2:$K$8001,1,MQLs!$G$2:$G$8001,1)-(COUNTIFS(MQLs!$E$2:$E$8001,$A12,MQLs!$K$2:$K$8001,1,MQLs!$D$2:$D$8001,$B$4,MQLs!$G$2:$G$8001,1)+COUNTIFS(MQLs!$E$2:$E$8001,$A12,MQLs!$K$2:$K$8001,1,MQLs!$D$2:$D$8001,$B$5,MQLs!$G$2:$G$8001,1)))/D12,0) | F12: =(C12-E12)*100
A14: Top pages win by 10-15 points in organic, direct, referral and unknown traffic, but not in paid search. Next step: A/B test sending organic traffic to the top page.

Sheet Time to Close
A1: Time to Close (analysis window)
A2: Days from first contact to won deal
A4: Time to close | B4: From (days) | C4: To (days) | D4: Deals | E4: Share | F4: Cumulative
A5: 0-7 days | B5: 0 | C5: 7 | D5: =COUNTIFS(MQLs!$K$2:$K$8001,1,MQLs!$J$2:$J$8001,">="&B5,MQLs!$J$2:$J$8001,"<="&C5) | E5: =IFERROR(D5/SUM($D$5:$D$8),0) | F5: =SUM($E$5:E5)
A6: 8-30 days | B6: 8 | C6: 30 | D6: =COUNTIFS(MQLs!$K$2:$K$8001,1,MQLs!$J$2:$J$8001,">="&B6,MQLs!$J$2:$J$8001,"<="&C6) | E6: =IFERROR(D6/SUM($D$5:$D$8),0) | F6: =SUM($E$5:E6)
A7: 31-90 days | B7: 31 | C7: 90 | D7: =COUNTIFS(MQLs!$K$2:$K$8001,1,MQLs!$J$2:$J$8001,">="&B7,MQLs!$J$2:$J$8001,"<="&C7) | E7: =IFERROR(D7/SUM($D$5:$D$8),0) | F7: =SUM($E$5:E7)
A8: Over 90 days | B8: 91 | C8: 9999 | D8: =COUNTIFS(MQLs!$K$2:$K$8001,1,MQLs!$J$2:$J$8001,">="&B8,MQLs!$J$2:$J$8001,"<="&C8) | E8: =IFERROR(D8/SUM($D$5:$D$8),0) | F8: =SUM($E$5:E8)
A10: Median days to close | D10: {=MEDIAN(IF((MQLs!$K$2:$K$8001=1)*ISNUMBER(MQLs!$J$2:$J$8001),MQLs!$J$2:$J$8001))}
A11: (array formula – in old Excel versions confirm with Ctrl+Shift+Enter)

Sheet Closers
A1: Sales Rep Concentration (analysis window)
A2: Deals closed per sales rep (sr_id), largest first – a Pareto view
A4: Rank | B4: Sales rep id | C4: Deals | D4: Share | E4: Cumulative share
A5: 1 | B5: 4ef15afb4b2723d8f3d81e51ec7afefe | C5: =COUNTIFS(MQLs!$I$2:$I$8001,$B5,MQLs!$K$2:$K$8001,1) | D5: =IFERROR(C5/SUM($C$5:$C$25),0) | E5: =SUM($D$5:D5) | G5: Reps needed for 50% of deals | J5: =COUNTIF(E5:E25,"<0.5")+1
A6: 2 | B6: d3d1e91a157ea7f90548eef82f1955e3 | C6: =COUNTIFS(MQLs!$I$2:$I$8001,$B6,MQLs!$K$2:$K$8001,1) | D6: =IFERROR(C6/SUM($C$5:$C$25),0) | E6: =SUM($D$5:D6) | G6: Total reps with deals | J6: =COUNTIF(C5:C25,">0")
A7: 3 | B7: 6565aa9ce3178a5caf6171827af3a9ba | C7: =COUNTIFS(MQLs!$I$2:$I$8001,$B7,MQLs!$K$2:$K$8001,1) | D7: =IFERROR(C7/SUM($C$5:$C$25),0) | E7: =SUM($D$5:D7)
A8: 4 | B8: 85fc447d336637ba1df43e793199fbc8 | C8: =COUNTIFS(MQLs!$I$2:$I$8001,$B8,MQLs!$K$2:$K$8001,1) | D8: =IFERROR(C8/SUM($C$5:$C$25),0) | E8: =SUM($D$5:D8) | G8: Key-person risk: losing the top rep would remove ~1 in 6 deals.
A9: 5 | B9: fbf4aef3f6915dc0c3c97d6812522f6a | C9: =COUNTIFS(MQLs!$I$2:$I$8001,$B9,MQLs!$K$2:$K$8001,1) | D9: =IFERROR(C9/SUM($C$5:$C$25),0) | E9: =SUM($D$5:D9)
A10: 6 | B10: 2695de1affa7750089c0455f8ce27021 | C10: =COUNTIFS(MQLs!$I$2:$I$8001,$B10,MQLs!$K$2:$K$8001,1) | D10: =IFERROR(C10/SUM($C$5:$C$25),0) | E10: =SUM($D$5:D10)
A11: 7 | B11: 495d4e95a8cf8bbf8b432b612a2aa328 | C11: =COUNTIFS(MQLs!$I$2:$I$8001,$B11,MQLs!$K$2:$K$8001,1) | D11: =IFERROR(C11/SUM($C$5:$C$25),0) | E11: =SUM($D$5:D11)
A12: 8 | B12: 9ae085775a198122c5586fa830ff7f2b | C12: =COUNTIFS(MQLs!$I$2:$I$8001,$B12,MQLs!$K$2:$K$8001,1) | D12: =IFERROR(C12/SUM($C$5:$C$25),0) | E12: =SUM($D$5:D12)
A13: 9 | B13: de63de0d10a6012430098db33c679b0b | C13: =COUNTIFS(MQLs!$I$2:$I$8001,$B13,MQLs!$K$2:$K$8001,1) | D13: =IFERROR(C13/SUM($C$5:$C$25),0) | E13: =SUM($D$5:D13)
A14: 10 | B14: c638112b43f1d1b86dcabb0da720c901 | C14: =COUNTIFS(MQLs!$I$2:$I$8001,$B14,MQLs!$K$2:$K$8001,1) | D14: =IFERROR(C14/SUM($C$5:$C$25),0) | E14: =SUM($D$5:D14)
A15: 11 | B15: 060c0a26f19f4d66b42e0d8796688490 | C15: =COUNTIFS(MQLs!$I$2:$I$8001,$B15,MQLs!$K$2:$K$8001,1) | D15: =IFERROR(C15/SUM($C$5:$C$25),0) | E15: =SUM($D$5:D15)
A16: 12 | B16: a8387c01a09e99ce014107505b92388c | C16: =COUNTIFS(MQLs!$I$2:$I$8001,$B16,MQLs!$K$2:$K$8001,1) | D16: =IFERROR(C16/SUM($C$5:$C$25),0) | E16: =SUM($D$5:D16)
A17: 13 | B17: 068066e24f0c643eb1d089c7dd20cd73 | C17: =COUNTIFS(MQLs!$I$2:$I$8001,$B17,MQLs!$K$2:$K$8001,1) | D17: =IFERROR(C17/SUM($C$5:$C$25),0) | E17: =SUM($D$5:D17)
A18: 14 | B18: 9e4d1098a3b0f5da39b0bc48f9876645 | C18: =COUNTIFS(MQLs!$I$2:$I$8001,$B18,MQLs!$K$2:$K$8001,1) | D18: =IFERROR(C18/SUM($C$5:$C$25),0) | E18: =SUM($D$5:D18)
A19: 15 | B19: 56bf83c4bb35763a51c2baab501b4c67 | C19: =COUNTIFS(MQLs!$I$2:$I$8001,$B19,MQLs!$K$2:$K$8001,1) | D19: =IFERROR(C19/SUM($C$5:$C$25),0) | E19: =SUM($D$5:D19)
A20: 16 | B20: 34d40cdaf94010a1d05b0d6212f9e909 | C20: =COUNTIFS(MQLs!$I$2:$I$8001,$B20,MQLs!$K$2:$K$8001,1) | D20: =IFERROR(C20/SUM($C$5:$C$25),0) | E20: =SUM($D$5:D20)
... A25: 21 | B25: b90f87164b5f8c2cfa5c8572834dbe3f | C25: =COUNTIFS(MQLs!$I$2:$I$8001,$B25,MQLs!$K$2:$K$8001,1) | D25: =IFERROR(C25/SUM($C$5:$C$25),0) | E25: =SUM($D$5:D25)

Sheet Data Quality
A1: Data Quality Checks
A2: Real data is never clean – these checks shape the conclusions
A4: Check | B4: Value | C4: Share | D4: What it means
A5: Leads (MQLs) | B5: =COUNTA(MQLs!$A$2:$A$8001) | D5: Jun 2017 – May 2018
A6: Deals | B6: =COUNTA(Deals!$A$2:$A$843) | D6: Won Dec 2017 – Nov 2018: earlier deals are missing
A7: Deals that matched a lead | B7: =SUM(MQLs!$G$2:$G$8001) | C7: =B7/B6 | D7: Should be 100% – join integrity
A8: Leads with origin 'unknown' or missing | B8: =COUNTIF(MQLs!$E$2:$E$8001,"unknown")+COUNTIF(MQLs!$E$2:$E$8001,"(missing)") | C8: =B8/B5 | D8: Tracking gap – and these leads convert best
A9: Deals won before first contact | B9: =COUNTIF(MQLs!$J$2:$J$8001,"<0") | C9: =B9/B6 | D9: Impossible date – excluded from timing
A10: Deals with declared revenue = 0 | B10: =COUNTIF(Deals!$N$2:$N$843,0) | C10: =B10/B6 | D10: Revenue field unusable – no value analysis
A11: Deals with has_company empty | B11: =COUNTBLANK(Deals!$I$2:$I$843) | C11: =B11/B6 | D11: Field mostly empty – not used

Sheet MQLs
A1: mql_id | B1: first_contact_date | C1: lead_month | D1: landing_page_id | E1: origin | F1: deal_row | G1: is_won | H1: won_date | I1: sr_id | J1: days_to_close | K1: in_window
A2: dac32acd4db4c29c230538b72f8dd87d | B2: 43132 | C2: 2018-02 | D2: 88740e65d5d6b056e0cda098e1ea6313 | E2: social | F2: =IFERROR(MATCH(A2,Deals!$A$2:$A$843,0),"") | G2: =IF(F2="",0,1) | H2: =IF(F2="","",INDEX(Deals!$E$2:$E$843,F2)) | I2: =IF(F2="","",INDEX(Deals!$D$2:$D$843,F2)) | J2: =IF(F2="","",INT(H2)-B2) | K2: =IF(B2>=Settings!$C$5,1,0)
A3: 8c18d1de7f67e60dbd64e3c07d7e9d5d | B3: 43028 | C3: 2017-10 | D3: 007f9098284a86ee80ddeb25d53e0af8 | E3: paid_search | F3: =IFERROR(MATCH(A3,Deals!$A$2:$A$843,0),"") | G3: =IF(F3="",0,1) | H3: =IF(F3="","",INDEX(Deals!$E$2:$E$843,F3)) | I3: =IF(F3="","",INDEX(Deals!$D$2:$D$843,F3)) | J3: =IF(F3="","",INT(H3)-B3) | K3: =IF(B3>=Settings!$C$5,1,0)
A4: b4bc852d233dfefc5131f593b538befa | B4: 43181 | C4: 2018-03 | D4: a7982125ff7aa3b2054c6e44f9d28522 | E4: organic_search | F4: =IFERROR(MATCH(A4,Deals!$A$2:$A$843,0),"") | G4: =IF(F4="",0,1) | H4: =IF(F4="","",INDEX(Deals!$E$2:$E$843,F4)) | I4: =IF(F4="","",INDEX(Deals!$D$2:$D$843,F4)) | J4: =IF(F4="","",INT(H4)-B4) | K4: =IF(B4>=Settings!$C$5,1,0)
A5: 6be030b81c75970747525b843c1ef4f8 | B5: 43122 | C5: 2018-01 | D5: d45d558f0daeecf3cccdffe3c59684aa | E5: email | F5: =IFERROR(MATCH(A5,Deals!$A$2:$A$843,0),"") | G5: =IF(F5="",0,1) | H5: =IF(F5="","",INDEX(Deals!$E$2:$E$843,F5)) | I5: =IF(F5="","",INDEX(Deals!$D$2:$D$843,F5)) | J5: =IF(F5="","",INT(H5)-B5) | K5: =IF(B5>=Settings!$C$5,1,0)
A6: 5420aad7fec3549a85876ba1c529bd84 | B6: 43152 | C6: 2018-02 | D6: b48ec5f3b04e9068441002a19df93c6c | E6: organic_search | F6: =IFERROR(MATCH(A6,Deals!$A$2:$A$843,0),"") | G6: =IF(F6="",0,1) | H6: =IF(F6="","",INDEX(Deals!$E$2:$E$843,F6)) | I6: =IF(F6="","",INDEX(Deals!$D$2:$D$843,F6)) | J6: =IF(F6="","",INT(H6)-B6) | K6: =IF(B6>=Settings!$C$5,1,0)
A7: 28bdfd5f057764b54c38770f95c69f2f | B7: 43114 | C7: 2018-01 | D7: 22c29808c4f815213303f8933030604c | E7: organic_search | F7: =IFERROR(MATCH(A7,Deals!$A$2:$A$843,0),"") | G7: =IF(F7="",0,1) | H7: =IF(F7="","",INDEX(Deals!$E$2:$E$843,F7)) | I7: =IF(F7="","",INDEX(Deals!$D$2:$D$843,F7)) | J7: =IF(F7="","",INT(H7)-B7) | K7: =IF(B7>=Settings!$C$5,1,0)
A8: 126a0d10becbaafcb2e72ce6848cf32c | B8: 43235 | C8: 2018-05 | D8: 6a110e795dd487f1cf8d7583671987af | E8: email | F8: =IFERROR(MATCH(A8,Deals!$A$2:$A$843,0),"") | G8: =IF(F8="",0,1) | H8: =IF(F8="","",INDEX(Deals!$E$2:$E$843,F8)) | I8: =IF(F8="","",INDEX(Deals!$D$2:$D$843,F8)) | J8: =IF(F8="","",INT(H8)-B8) | K8: =IF(B8>=Settings!$C$5,1,0)
A9: f76136f54d14a3345951f25b7932366b | B9: 43244 | C9: 2018-05 | D9: d51b0d02f063ba1d053db6d97226eec3 | E9: email | F9: =IFERROR(MATCH(A9,Deals!$A$2:$A$843,0),"") | G9: =IF(F9="",0,1) | H9: =IF(F9="","",INDEX(Deals!$E$2:$E$843,F9)) | I9: =IF(F9="","",INDEX(Deals!$D$2:$D$843,F9)) | J9: =IF(F9="","",INT(H9)-B9) | K9: =IF(B9>=Settings!$C$5,1,0)
A10: 2f838cade4a6012a6cb1016d1d8d95ed | B10: 43049 | C10: 2017-11 | D10: aeac92c0f5ae22a04ed3b746cce3a1b6 | E10: organic_search | F10: =IFERROR(MATCH(A10,Deals!$A$2:$A$843,0),"") | G10: =IF(F10="",0,1) | H10: =IF(F10="","",INDEX(Deals!$E$2:$E$843,F10)) | I10: =IF(F10="","",INDEX(Deals!$D$2:$D$843,F10)) | J10: =IF(F10="","",INT(H10)-B10) | K10: =IF(B10>=Settings!$C$5,1,0)
A11: 7281942387a1a0c3f72a50a8b0bb0920 | B11: 43094 | C11: 2017-12 | D11: 88740e65d5d6b056e0cda098e1ea6313 | E11: social | F11: =IFERROR(MATCH(A11,Deals!$A$2:$A$843,0),"") | G11: =IF(F11="",0,1) | H11: =IF(F11="","",INDEX(Deals!$E$2:$E$843,F11)) | I11: =IF(F11="","",INDEX(Deals!$D$2:$D$843,F11)) | J11: =IF(F11="","",INT(H11)-B11) | K11: =IF(B11>=Settings!$C$5,1,0)
A12: c534e2f89539e866011e1e75adfefbfb | B12: 43124 | C12: 2018-01 | D12: f017be4dbf86243af5c1ebed0cff36a2 | E12: unknown | F12: =IFERROR(MATCH(A12,Deals!$A$2:$A$843,0),"") | G12: =IF(F12="",0,1) | H12: =IF(F12="","",INDEX(Deals!$E$2:$E$843,F12)) | I12: =IF(F12="","",INDEX(Deals!$D$2:$D$843,F12)) | J12: =IF(F12="","",INT(H12)-B12) | K12: =IF(B12>=Settings!$C$5,1,0)
A13: c3764ab3fed8fbf556c87fdeaea744a9 | B13: 43220 | C13: 2018-04 | D13: 35c9b150ab36fe584c1f24fd458c453a | E13: paid_search | F13: =IFERROR(MATCH(A13,Deals!$A$2:$A$843,0),"") | G13: =IF(F13="",0,1) | H13: =IF(F13="","",INDEX(Deals!$E$2:$E$843,F13)) | I13: =IF(F13="","",INDEX(Deals!$D$2:$D$843,F13)) | J13: =IF(F13="","",INT(H13)-B13) | K13: =IF(B13>=Settings!$C$5,1,0)
... A8001: 8a6492305a5fbcdcdd1a7f5a90764c07 | B8001: 43111 | C8001: 2018-01 | D8001: b76ef37428e6799c421989521c0e5077 | E8001: direct_traffic | F8001: =IFERROR(MATCH(A8001,Deals!$A$2:$A$843,0),"") | G8001: =IF(F8001="",0,1) | H8001: =IF(F8001="","",INDEX(Deals!$E$2:$E$843,F8001)) | I8001: =IF(F8001="","",INDEX(Deals!$D$2:$D$843,F8001)) | J8001: =IF(F8001="","",INT(H8001)-B8001) | K8001: =IF(B8001>=Settings!$C$5,1,0)

Sheet Deals
A1: mql_id | B1: seller_id | C1: sdr_id | D1: sr_id | E1: won_date | F1: business_segment | G1: lead_type | H1: lead_behaviour_profile | I1: has_company | J1: has_gtin | K1: average_stock | L1: business_type | M1: declared_product_catalog_size | N1: declared_monthly_revenue
A2: 5420aad7fec3549a85876ba1c529bd84 | B2: 2c43fb513632d29b3b58df74816f1b06 | C2: a8387c01a09e99ce014107505b92388c | D2: 4ef15afb4b2723d8f3d81e51ec7afefe | E2: 43157.833 | F2: pet | G2: online_medium | H2: cat | L2: reseller | N2: 0
A3: a555fb36b9368110ede0f043dfc3b9a0 | B3: bbb7d7893a450660432ea6652310ebb7 | C3: 09285259593c61296eef10c734121d5b | D3: d3d1e91a157ea7f90548eef82f1955e3 | E3: 43228.846 | F3: car_accessories | G3: industry | H3: eagle | L3: reseller | N3: 0
A4: 327174d3648a2d047e8940d7d15204ca | B4: 612170e34b97004b3ba37eae81836b4c | C4: b90f87164b5f8c2cfa5c8572834dbe3f | D4: 6565aa9ce3178a5caf6171827af3a9ba | E4: 43256.727 | F4: home_appliances | G4: online_big | H4: cat | L4: reseller | N4: 0
A5: f5fee8f7da74f4887f5bcae2bafb6dd6 | B5: 21e1781e36faf92725dde4730a88ca0f | C5: 56bf83c4bb35763a51c2baab501b4c67 | D5: d3d1e91a157ea7f90548eef82f1955e3 | E5: 43117.577 | F5: food_drink | G5: online_small | L5: reseller | N5: 0
A6: ffe640179b554e295c167a2f6be528e0 | B6: ed8cb7b190ceb6067227478e48cf8dde | C6: 4b339f9567d060bcea4f5136b9f5949e | D6: d3d1e91a157ea7f90548eef82f1955e3 | E6: 43284.846 | F6: home_appliances | G6: industry | H6: wolf | L6: manufacturer | N6: 0
A7: b94fba7670eeb44dce2a0d8eb790e9f5 | B7: 1c742ac33582852aaf3bcfbf5893abcf | C7: fdb16d3cbbeb5798f2f66c4096be026d | D7: 495d4e95a8cf8bbf8b432b612a2aa328 | E7: 43138.753 | F7: health_beauty | G7: online_medium | L7: manufacturer | N7: 0
A8: c3e30ed7ac989117c7e1e719b4ac128f | B8: 92d7568ad0c5c76fd7d341b2d46f24d6 | C8: 4b339f9567d060bcea4f5136b9f5949e | D8: 85fc447d336637ba1df43e793199fbc8 | E8: 43206.763 | F8: computers | G8: online_medium | H8: wolf | L8: reseller | N8: 0
A9: b02c89251106e1fdd9d92744be9f94f2 | B9: 44ed138eca6214d572ce1d813fb0049b | C9: 34d40cdaf94010a1d05b0d6212f9e909 | D9: 4ef15afb4b2723d8f3d81e51ec7afefe | E9: 43207.71 | F9: health_beauty | G9: offline | H9: cat | L9: manufacturer | N9: 0
A10: a90a37898cc5f2718385a2fb981caaff | B10: 0b28859cd04d23edefee9c591fb03cd8 | C10: f42a2bd194f7802ab052a815c8de65b7 | D10: 6565aa9ce3178a5caf6171827af3a9ba | E10: 43234.776 | F10: household_utilities | G10: offline | H10: eagle | L10: reseller | N10: 0
A11: 0173e8d8b1d94a355b440fb67388f532 | B11: 87d73636a3acf123e842bb890a4db036 | C11: 9d12ef1a7eca3ec58c545c678af7869c | D11: 9e4d1098a3b0f5da39b0bc48f9876645 | E11: 43214.125 | F11: household_utilities | G11: online_medium | H11: eagle | L11: manufacturer | N11: 0
A12: 4e4e70d504b4c0006c8287dedc99d0fc | B12: f7a0d94e966c5665355a182d5b199fcf | C12: fdb16d3cbbeb5798f2f66c4096be026d | D12: 4ef15afb4b2723d8f3d81e51ec7afefe | E12: 43159.821 | F12: construction_tools_house_garden | G12: online_medium | H12: cat | L12: reseller | N12: 0
A13: 408a9c4a79800232ac656249af3162eb | B13: b566ab0ef88016e00422755e305103c6 | C13: de63de0d10a6012430098db33c679b0b | D13: d3d1e91a157ea7f90548eef82f1955e3 | E13: 43154.58 | F13: construction_tools_house_garden | G13: online_big | H13: cat | L13: reseller | N13: 0
A14: c556184b3fe2087834850b68fa435cee | B14: 2d2322d842118867781fc737e96d59a1 | C14: 09285259593c61296eef10c734121d5b | D14: 2695de1affa7750089c0455f8ce27021 | E14: 43242.558 | F14: household_utilities | G14: online_medium | H14: cat | L14: reseller | N14: 0
A15: 67455a0673f5cf26deae5b270c003e83 | B15: e7012030d0fdd1d3ca504f6de7909c35 | C15: 4b339f9567d060bcea4f5136b9f5949e | D15: 9ae085775a198122c5586fa830ff7f2b | E15: 43265.604 | F15: toys | G15: online_big | H15: wolf | L15: reseller | N15: 0
A16: ab11f58a6bf7036a656364b0ba68fb74 | B16: 9e7c5f4d7770eab65738cca38f9efccf | C16: 068066e24f0c643eb1d089c7dd20cd73 | D16: de63de0d10a6012430098db33c679b0b | E16: 43200.125 | F16: sports_leisure | G16: online_medium | H16: cat | L16: reseller | N16: 0
A17: bae38661a27f6228ba38c36e766ed769 | B17: 6a6b1614baaaf766293c17d8cb8c5a9d | C17: f42a2bd194f7802ab052a815c8de65b7 | D17: 495d4e95a8cf8bbf8b432b612a2aa328 | E17: 43353.596 | F17: stationery | G17: industry | H17: cat | K17: 20-50 | L17: reseller | M17: 2000 | N17: 100000
A18: 450b97a48568c3118ff397f73abe4e4a | B18: df91910b6a03bb2e3358fa6a35e32f6f | C18: 09285259593c61296eef10c734121d5b | D18: 060c0a26f19f4d66b42e0d8796688490 | E18: 43200.807 | F18: food_drink | G18: online_medium | H18: cat | L18: manufacturer | N18: 0
A19: 9878253904482726e741460a99adba86 | B19: 92d46311e4fa7583d14c351fdc881af6 | C19: de63de0d10a6012430098db33c679b0b | D19: 4ef15afb4b2723d8f3d81e51ec7afefe | E19: 43126.725 | F19: food_supplement | G19: industry | L19: manufacturer | N19: 0
A20: ed3d878bf23177e7075ce07578841047 | B20: 249f0e9905a6e06ad6c6bea7547ab9f6 | C20: 9d12ef1a7eca3ec58c545c678af7869c | D20: fbf4aef3f6915dc0c3c97d6812522f6a | E20: 43231.794 | F20: home_decor | G20: online_medium | H20: cat | L20: manufacturer | N20: 0
A21: 119ce5d79e3c006a9e46967bff271cb2 | B21: b494891378bd8f4560abe576c52deacd | C21: b90f87164b5f8c2cfa5c8572834dbe3f | D21: 4ef15afb4b2723d8f3d81e51ec7afefe | E21: 43270.589 | F21: health_beauty | G21: online_top | H21: cat | L21: reseller | N21: 0
A22: 1f4e960dc47c49ab5c2a495e00055f64 | B22: 8c45b4bc4b5c1e2a4e789b4466a39b77 | C22: 56bf83c4bb35763a51c2baab501b4c67 | D22: c638112b43f1d1b86dcabb0da720c901 | E22: 43138.581 | F22: bed_bath_table | G22: offline | L22: reseller | N22: 0
A23: 05d287893f5f083739da863da2c4b6f8 | B23: 49f6ca9231352dedda1ad1176ce70531 | C23: 9e4d1098a3b0f5da39b0bc48f9876645 | D23: 060c0a26f19f4d66b42e0d8796688490 | E23: 43206.548 | F23: health_beauty | G23: online_small | H23: cat | L23: reseller | N23: 0
A24: 0b97be8b4b408a3a0780a32e0a143a7f | B24: 7d13fca15225358621be4086e1eb0964 | C24: 56bf83c4bb35763a51c2baab501b4c67 | D24: 9ae085775a198122c5586fa830ff7f2b | E24: 43139.722 | F24: watches | G24: online_big | L24: reseller | N24: 0
A25: 2552a7b886c1710f36be92ac29b1362d | B25: efa89b428cbc422ba9313b4fc6feafc7 | C25: 56bf83c4bb35763a51c2baab501b4c67 | D25: d3d1e91a157ea7f90548eef82f1955e3 | E25: 43147.522 | F25: fashion_accessories | G25: online_beginner | L25: manufacturer | N25: 0
A26: 59c0665c39a2bb9c8776d66f4e8b8f66 | B26: cb3666965a560e723403683bd378a5f7 | C26: fdb16d3cbbeb5798f2f66c4096be026d | D26: 4ef15afb4b2723d8f3d81e51ec7afefe | E26: 43153.528 | F26: jewerly | G26: online_medium | L26: manufacturer | N26: 0
A27: 4151b0029636a1c55afcce9283ac7902 | B27: e819bcfade7b5d88a27325eb6cfd62c5 | C27: 068066e24f0c643eb1d089c7dd20cd73 | D27: 9ae085775a198122c5586fa830ff7f2b | E27: 43143.554 | F27: home_decor | G27: industry | L27: manufacturer | N27: 0
A28: fc4166d1b1e192f650ee2d807b54c943 | B28: 70c27847eca8195c983ed7e798c56743 | C28: fdb16d3cbbeb5798f2f66c4096be026d | D28: 4ef15afb4b2723d8f3d81e51ec7afefe | E28: 43139.873 | F28: pet | G28: online_small | L28: reseller | N28: 0
A29: 85e43237b3fb87d881c757f44f1b0357 | B29: 556a6409838156ea299c9d1f9e2dde43 | C29: 4b339f9567d060bcea4f5136b9f5949e | D29: fbf4aef3f6915dc0c3c97d6812522f6a | E29: 43196.87 | F29: household_utilities | G29: industry | H29: shark | L29: reseller | N29: 0
A30: 9ce2e101957dc53e3e89cc8e1599aa60 | B30: a4fc6eadaff1576af888509a53420f6a | C30: 09285259593c61296eef10c734121d5b | D30: 6565aa9ce3178a5caf6171827af3a9ba | E30: 43203.519 | F30: computers | G30: online_beginner | H30: cat | L30: reseller | N30: 0
A31: 9a6b65aedf8177783035f3a53ca21ed1 | B31: 0975b0dd18febd1008391fa53dff0891 | C31: 370c9f455f93a9a96cbe9bea48e70033 | D31: 85fc447d336637ba1df43e793199fbc8 | E31: 43208.751 | F31: party | G31: online_medium | H31: eagle | L31: manufacturer | N31: 0
A32: 4bb1ec1ff58ad39558e8468054bfc469 | B32: 4fae87d32467e18eb46e4a76a0a0b9ce | C32: 9d12ef1a7eca3ec58c545c678af7869c | D32: a8387c01a09e99ce014107505b92388c | E32: 43300.754 | F32: small_appliances | G32: online_medium | H32: cat | I32: TRUE | J32: TRUE | K32: 20-50 | L32: reseller | N32: 0
A33: c34eb63cd098bf4be03d53462d7ecba2 | B33: 3525be8392a4fa3274c459bcfee41eef | C33: 4b339f9567d060bcea4f5136b9f5949e | D33: de63de0d10a6012430098db33c679b0b | E33: 43285.63 | F33: food_supplement | G33: online_small | H33: cat | L33: reseller | N33: 0
A34: e428d5580f729d23e6070e43c492e424 | B34: 8b181ee5518df84f18f4e1a43fe07923 | C34: 09285259593c61296eef10c734121d5b | D34: de63de0d10a6012430098db33c679b0b | E34: 43215.125 | F34: health_beauty | G34: online_medium | H34: shark | L34: reseller | N34: 0
A35: e3c91316d8f28b18d96869aebbb7c3ec | B35: d594982fd877af63ace38ea1fca27c76 | C35: 09285259593c61296eef10c734121d5b | D35: fbf4aef3f6915dc0c3c97d6812522f6a | E35: 43256.723 | F35: audio_video_electronics | G35: industry | H35: wolf | L35: reseller | N35: 0
A36: 72e81de94dfc0373b006ca75e9c851a1 | B36: 2f1e89e231b096f4ff1f55dfe8607a7b | C36: e7dff61b78bebffa71678e126ce669ad | D36: 068066e24f0c643eb1d089c7dd20cd73 | E36: 43404.705 | F36: computers | G36: online_medium | H36: cat | I36: TRUE | K36: 1-5 | L36: reseller | M36: 80 | N36: 0
A37: 1cbfa9c878ef8692c1ae21e4cfa11000 | B37: 90269579385b838ce9bd577dcec278a4 | C37: 34d40cdaf94010a1d05b0d6212f9e909 | D37: 85fc447d336637ba1df43e793199fbc8 | E37: 43250.614 | F37: pet | G37: industry | H37: cat | L37: manufacturer | N37: 0
A38: b055fc7de322786cd9ddc996cb6e72ff | B38: 398cb257329ef7af7f1943a8974a3cbc | C38: a8387c01a09e99ce014107505b92388c | D38: 9ae085775a198122c5586fa830ff7f2b | E38: 43165.518 | F38: food_drink | G38: online_medium | H38: cat | L38: manufacturer | N38: 0
A39: a8d2884db49e0769ad4a0b8dce2e143c | B39: d65f74c704563bcb8baa915fbf8cfa1e | C39: 6aa3b86a83d784b05f0e37e26b20860d | D39: de63de0d10a6012430098db33c679b0b | E39: 43370.522 | F39: health_beauty | G39: online_medium | H39: cat | J39: FALSE | L39: reseller | M39: 15 | N39: 20000
A40: d955b97b28c2966211c9de2fe22fefbd | B40: 26e2c91ef821e1ff8985f408788fe35b | C40: 4b339f9567d060bcea4f5136b9f5949e | D40: 6565aa9ce3178a5caf6171827af3a9ba | E40: 43137.657 | F40: bed_bath_table | G40: online_beginner | L40: manufacturer | N40: 0
...
